{
    "title": "An issue was discovered in the pyo3 crate before 0.12.4 for Rust. There is a reference-counting error and use-after-free in From<Py<T>>.",
    "score": 5.5,
    "severity": "MEDIUM",
    "cwe_id": "CWE-416",
    "cvss_vector": "CVSS:3.1/AV:L/AC:L/PR:L/UI:N/S:U/C:N/I:N/A:H",
    "cpe_match": [
        "cpe:2.3:a:pyo3_project:pyo3:*:*:*:*:*:rust:*:*"
    ],
    "cve_source": [
        "NVD"
    ],
    "ttpMapping": [
        {
            "techniqueId": "T1059",
            "confidence": "2.2",
            "techniqueName": "Command and Scripting Interpreter"
        },
        {
            "techniqueId": "T1123",
            "confidence": "2.0",
            "techniqueName": "Audio Capture"
        },
        {
            "techniqueId": "T1057",
            "confidence": "4.3",
            "techniqueName": "Process Discovery"
        },
        {
            "techniqueId": "T1059",
            "confidence": "3.4",
            "techniqueName": "Command and Scripting Interpreter"
        },
        {
            "techniqueId": "T1087",
            "confidence": "4.1",
            "techniqueName": "Account Discovery"
        },
        {
            "techniqueId": "T1123",
            "confidence": "6.2",
            "techniqueName": "Audio Capture"
        },
        {
            "techniqueId": "T1213",
            "confidence": "3.2",
            "techniqueName": "Data from Information Repositories"
        },
        {
            "techniqueId": "T1489",
            "confidence": "5.2",
            "techniqueName": "Service Stop"
        }
    ]
}
