{
    "title": "An exception is thrown from a function in AVEVA System Platform versions 2017 through 2020 R2 P01, but it is not caught, which may cause a denial-of-service condition.",
    "score": 7.5,
    "severity": "HIGH",
    "cwe_id": "NVD-CWE-Other",
    "cvss_vector": "CVSS:3.1/AV:N/AC:L/PR:N/UI:N/S:U/C:N/I:N/A:H",
    "cpe_match": [
        "cpe:2.3:a:aveva:system_platform:2020:r2_p01:*:*:*:*:*:*",
        "cpe:2.3:a:aveva:system_platform:2020:r2:*:*:*:*:*:*",
        "cpe:2.3:a:aveva:system_platform:2020:-:*:*:*:*:*:*",
        "cpe:2.3:a:aveva:system_platform:*:*:*:*:*:*:*:*"
    ],
    "cve_source": [
        "NVD"
    ],
    "ttpMapping": []
}
