{
    "title": "Race condition in the FTPHandler class in ftpserver.py in pyftpdlib before 0.5.2 allows remote attackers to cause a denial of service (daemon outage) by establishing and then immediately closing a TCP connection, leading to the accept function having an unexpected value of None for the address, or an ECONNABORTED, EAGAIN, or EWOULDBLOCK error, a related issue to CVE-2010-3492.",
    "score": 4.3,
    "severity": "MEDIUM",
    "cwe_id": "CWE-362",
    "cvss_vector": "CVSS:2.0/AV:N/AC:M/Au:N/C:N/I:N/A:P",
    "cpe_match": [
        "cpe:2.3:a:g.rodola:pyftpdlib:0.5.0:*:*:*:*:*:*:*",
        "cpe:2.3:a:g.rodola:pyftpdlib:0.4.0:*:*:*:*:*:*:*",
        "cpe:2.3:a:g.rodola:pyftpdlib:0.2.0:*:*:*:*:*:*:*",
        "cpe:2.3:a:g.rodola:pyftpdlib:0.1:*:*:*:*:*:*:*",
        "cpe:2.3:a:g.rodola:pyftpdlib:0.1.1:*:*:*:*:*:*:*",
        "cpe:2.3:a:g.rodola:pyftpdlib:*:*:*:*:*:*:*:*",
        "cpe:2.3:a:g.rodola:pyftpdlib:0.3.0:*:*:*:*:*:*:*"
    ],
    "cve_source": [
        "NVD"
    ],
    "ttpMapping": [
        {
            "techniqueId": "T1489",
            "techniqueName": "Service Stop",
            "confidence": "5.1"
        },
        {
            "techniqueId": "T1498",
            "techniqueName": "Network Denial of Service",
            "confidence": "9.6"
        },
        {
            "techniqueId": "T1499",
            "techniqueName": "Endpoint Denial of Service",
            "confidence": "10.2"
        },
        {
            "techniqueId": "T1529",
            "techniqueName": "System Shutdown/Reboot",
            "confidence": "2.4"
        },
        {
            "techniqueId": "T1557",
            "techniqueName": "Adversary-in-the-Middle",
            "confidence": "2.3"
        }
    ]
}
